Workbook
Name Anzeige_Text_1: #N/A
Name availablehours: '[1]P&L Input'!$H$20
Name exchangerate: '[1]Exchange Rates'!$B$48:$B$87
Name FACTOR: '[1]Input Machines'!$BQ$15:$BQ$19
Name FTE: '[1]P&L Input'!$H$16
Name grosshours: '[1]P&L Input'!$H$19
Name Labtyp: '[1]Data Others'!$A$1:$H$1
Name ok: [2]Start!$I$6
Name otherpersonnelcosts: '[1]P&L Input'!$H$35
Name pensionfunds: '[1]P&L Input'!$H$34
Name personnelcosts: '[1]P&L Input'!$H$31
Name productivehours: '[1]P&L Input'!$H$21
Name salary: '[1]P&L Input'!$H$32
Name scen: [3]Sensitivities!$J$4
Name socialcosts: '[1]P&L Input'!$H$33
Name sprache: [3]Start!$I$6

Sheet Instruction
A6: Pre Calculation Sheet
A7: Version: V202501
B9: Purpose of the sheet:
B10: This template is used in quotation phase, for pre-calculation of order profitability to support decision making on acquiring of project.
B11: Before signing contract, if final order amount is changed to initial approved quotation, pre-calculation needs to be updated.
B12: For each order >= 25KEUR (175KCNY/200KHKD/750KTWD), pre-calculation sheet has to be prepared. For MHS&SMN, each order >= 50KEUR (350KCNY/400KHKD/1500KTWD), pre-calculation sheet has to be prepared.
A15: 1) | B15: Instruction for departments
A17: 1 | B17: Sheets for department input: "Project info" , "Project cost" and “Lab cost“
B18: Blue fields to be input
A20: 2 | B20: Project info
B21: Profit Center and Quotation Price are MUST for input
A23: 3 | B23: Project cost - Production cost from own staff
B25: It's calculated based on own staff working hour * hourly cost rate
B26: Normally, Hourly cost rate is defined as one average rate per profit center and is based on annual Budget.
B27: Exception: for certain business unit, like IS, Hourly cost rate is defined as per business line (so called 'skillgroup' in SAP)
B29: Attention: if manager concerns about the reasonability of hourly cost rate based on Budget, pls discuss with Controlling
A31: 4 | B31: Project info - Cost from subcontracting (3rd party or IC office)
B33: If one project is handled by more than one GCN office, pre-calculation from intra office(s) for IC subcontracting cost above 25KEUR
B34: is also to be provided.
B35: Example: one IS order is signed in GZ office, but subcontracted to BJ office with subcontracting cost above 25KEUR. Pre-calculation
B36: sheet for IC order in BJ office is needed. Controller will combine pre-calculation in two offices for review of margin at GCN level.
A39: 5 | B39: Project cost - Cost from internal subcontract to other departments
B40: When an order is to be internally subcontracted to other departments, it could be charged either on hour or fixed price. For cases of charged on hour, Manager must list out the cost center, the cost would be calculated on hourly cost rate and number of hour. There would be possible an order is charged on hour and fixed price at the same time. For work that will be internally subcontracted to lab, such as EMC or BAT lab, and will be charged by hour. Please input plan hours in the sheet of "Lab cost", and the cost will be automatically link back to "Project cost" column 118
A44: 6 | B44: Project cost - Allocation cost simulation
B45: Any sales recognized from one order will be allocated by related cost in one profit center. There are two ways to calculate allocation costs: PA report, Allocation cost by hour = Own staff working hour * Hourly allocation cost rate PCA report, Allocation cost by sales = Total sales * Planned ratio of allocation cost / Total sales. Allocation cost simulation is used to add the GAP if allocation cost by hour is less than allocation cost by sales. If allocation cost by hour (total project) > = allocation cost by sales, allocation cost simulation = 0; If allocation cost by hour < allocation cost by sales, allocation cost simulation = GAP. Allocation cost simulation is calculated by order level in this template and allocated to product/item level based on sales, as there might be both positive and negative simulation in that level but can be offset in order level.
A55: 7 | B55: P&L Summary - Signature
B56: Signature and approval is needed according to value and approval limits per each management level.
A58: 2) | B58: Instruction for controllers
A60: 1 | B60: Sheets for controller input: "Controlling DataInput"
B61: needs be updated for each office, according to Budget of corresponding year, deletion or adding is not preferred. Otherwise, formula in other sheets needs to be reset.
A64: 2 | B64: Sheets for controller input: "Lab cost database"
B65: Please update or add new machine rate or hourly rate in "Lab cost database" when needed, data in "Lab cost" will automatically refreshed.

Sheet Instruction_AUD
A3: 1 | B3: Please input the light blue area
A5: 2 | B5: Sales Revenue by Category
B6: Sales Revenue | C6: Category
B7: WRAP | C7: CSR
B8: SA8000 | C8: CSR
B9: BSCI | C9: CSR
B10: CoC | C10: CSR
B11: SEDEX | C11: CSR
B12: RBA | C12: CSR
B13: ESG | C13: ESG
B14: CDP | C14: ESG
B15: GRS | C15: CSR
B16: ASI | C16: CSR
B17: BEPI | C17: CSR
B18: RSCI | C18: CSR

Sheet AUD Pre-cal
P1: BL | Q1: Center | R1: Hourly Rate in CNY | S1: Margin% | T1: Alternative allocation cost / Total Costs | U1: Hourly Rates / Allocation Costs | V1: Alternative allocation cost / Ext. sales | W1: Alternative allocation cost / IC sales
B2: Customer Name | C2: XXX | I2: Remark
B3: Service | C3: ESG | D3: =IFERROR(_xlfn.XLOOKUP(C3,P4:P5,Q4:Q5),"") -> 1350 | Q3: Center | R3: MD Rate in CNY | S3: Margin% | T3: Alternative allocation cost / Total Costs | U3: MD Rates / Allocation Costs | V3: Alternative allocation cost / Total sales | W3: Alternative allocation cost / Total sales
B4: Order create Center | D4: 2160 | E4: 4820 | F4: 2160 | G4: 4820 | P4: ESG | Q4: 1350 | R4: ='Hourly Rate'!F16 -> 681.98 | S4: ='P&L'!D65 -> 8.062119 | T4: ='P&L'!D69 -> 0.12559478 | U4: =R4*T4 -> 85.653125 | V4: ='P&L'!D68 -> 0.090531867 | W4: ='P&L'!D71 -> 0.036959988
D5: =D4&$D$3 -> 21601350 | E5: =E4&$D$3 -> 48201350 | F5: =F4&$D$3 -> 21601350 | G5: =G4&$D$3 -> 48201350 | H5: =H4&$D$3 -> 1350 | P5: CSR | Q5: 1351 | R5: ='Hourly Rate'!F17 -> 532.25 | S5: ='P&L'!E65 -> 2.8485585 | T5: ='P&L'!E69 -> 0.13773452 | U5: =R5*T5 -> 73.309197 | V5: ='P&L'!D69 -> 0.12559478 | W5: ='P&L'!E71 -> 0.14867205
D6: 报告 | E6: 鉴证 | F6: 咨询 | G6: 审核 | H6: Product 5 | P6: 1800 | Q6: 2160 | R6: 4820 | S6: 4830 | T6: 4840 | U6: 4850
B7: Service/Product (Description) | F7: 供应链尽职调查
B9: Order Value | C9: =SUM(D9:H9) -> 138000 | F9: 138000
B10: MD for onsite | C10: =SUM(D10:H10) -> 4 | F10: 4 | I10: 现场人天
B11: MD for offsite | C11: =SUM(D11:H11) -> 10 | F11: 10 | I11: 非现场人天
B12: MD for Quotation Phase | C12: =SUM(D12:H12) -> 0.5 | D12: =IF(D9>0,0.5*D$9/$C$9,0) -> 0 | E12: =IF(E9>0,0.5*E$9/$C$9,0) -> 0 | F12: =IF(F9>0,0.5*F$9/$C$9,0) -> 0.5 | G12: =IF(G9>0,0.5*G$9/$C$9,0) -> 0 | H12: =IF(H9>0,0.5*H$9/$C$9,0) -> 0 | I12: 报价，销售活动，述标等报价相关MD，假定0.5 MD，可调整
B13: MD for Travel (20% of Quotation MD) | C13: =SUM(D13:H13) -> 0.4 | D13: =D10*0.1 -> 0 | E13: =E10*0.1 -> 0 | F13: =F10*0.1 -> 0.4 | G13: =G10*0.1 -> 0 | H13: =H10*0.1 -> 0 | I13: 差旅时间，按照现场人天10%，可调整
B14: Total MD | C14: =SUM(D14:H14) -> 14.9 | D14: =D10+D12+D13+D11 -> 0 | E14: =E10+E12+E13+E11 -> 0 | F14: =F10+F12+F13+F11 -> 14.9 | G14: =G10+G12+G13+G11 -> 0 | H14: =H10+H12+H13+H11 -> 0
B15: IC Subcon Rate | D15: =IF(D$4="2160",80%,0) -> 0.8 | E15: =IF(E$4="2160",80%,0) -> 0 | F15: =IF(F$4="2160",80%,0) -> 0.8 | G15: =IF(G$4="2160",80%,0) -> 0 | H15: =IF(H$4="2160",80%,0) -> 0
B16: Hours | C16: =SUM(D16:H16) -> 119.2 | D16: =D14*8 -> 0 | E16: =E14*8 -> 0 | F16: =F14*8 -> 119.2 | G16: =G14*8 -> 0 | H16: =H14*8 -> 0
A18: - | B18: Subcontracting ext.-翻译费 | C18: =SUM(D18:H18) -> 15000 | F18: 15000
A19: - | B19: Subcontracting ext.-设计费 | C19: =SUM(D19:H19) -> 20000 | F19: 20000
A20: - | B20: Subcontracting ext.-差旅费 | C20: =SUM(D20:H20) -> 5000 | F20: 5000
A21: - | B21: Subcontracting ext.-Other | C21: =SUM(D21:H21) -> 0
A22: - | B22: Subcontracting IC | C22: =SUM(D22:H22) -> 0 | I22: 给其他office的分包
A23: - | B23: internal subcon | C23: =SUM(D23:H23) -> 0 | I23: 同个office给其他部门的分包，包括CSR部门
B24: Net Sales | C24: =SUM(D24:H24) -> 98000 | D24: =D9-SUM(D18:D23) -> 0 | E24: =E9-SUM(E18:E23) -> 0 | F24: =F9-SUM(F18:F23) -> 98000 | G24: =G9-SUM(G18:G23) -> 0 | H24: =H9-SUM(H18:H23) -> 0
B25: Other project related costs | C25: =SUM(D25:H25) -> 0
B26: MD Costs | C26: =SUM(D26:H26) -> 81292.016 | D26: =D16*D37 -> 0 | E26: =E16*E37 -> 0 | F26: =F16*F37 -> 81292.016 | G26: =G16*G37 -> 0 | H26: =H16*H37 -> 0
B27: Result of order (RO) | C27: =SUM(D27:H27) -> 16707.984 | D27: =D24-D25-D26 -> 0 | E27: =E24-E25-E26 -> 0 | F27: =F24-F25-F26 -> 16707.984 | G27: =G24-G25-G26 -> 0 | H27: =H24-H25-H26 -> 0
B28: RO-Margin % | C28: =IFERROR(C27/C9,0) -> 0.12107235 | D28: =IFERROR(D27/D9,0) -> 0 | E28: =IFERROR(E27/E9,0) -> 0 | F28: =IFERROR(F27/F9,0) -> 0.12107235 | G28: =IFERROR(G27/G9,0) -> 0 | H28: =IFERROR(H27/H9,0) -> 0
B29: Overhead | C29: =SUM(D29:H29) -> 2283.5451 | D29: =IF(D44<0,0,D44) -> 0 | E29: =IF(E44<0,0,E44) -> 0 | F29: =IF(F44<0,0,F44) -> 2283.5451 | G29: =IF(G44<0,0,G44) -> 0 | H29: =IF(H44<0,0,H44) -> 0
B30: Operating Result | C30: =C24-SUM(C25,C26,C29) -> 14424.439 | D30: =D24-SUM(D25,D26,D29) -> 0 | E30: =E24-SUM(E25,E26,E29) -> 0 | F30: =F24-SUM(F25,F26,F29) -> 14424.439 | G30: =G24-SUM(G25,G26,G29) -> 0 | H30: =H24-SUM(H25,H26,H29) -> 0
B31: Operating Margin | C31: =IFERROR(C30/(C9),0) -> 0.10452492 | D31: =IFERROR(D30/(D9),0) -> 0 | E31: =IFERROR(E30/(E9),0) -> 0 | F31: =IFERROR(F30/(F9),0) -> 0.10452492 | G31: =IFERROR(G30/(G9),0) -> 0 | H31: =IFERROR(H30/(H9),0) -> 0
B32: Planned OR/Sales | C32: =IFERROR(VLOOKUP($D$3,$Q$4:$S$5,3,0),0)/100 -> 0.08062119
B33: Subcontracing/Sales | C33: =IFERROR(SUM(C18:C22)/C9,"") -> 0.28985507 | D33: =IFERROR(SUM(D18:D22)/D9,"") | E33: =IFERROR(SUM(E18:E22)/E9,"") | F33: =IFERROR(SUM(F18:F22)/F9,"") -> 0.28985507 | G33: =IFERROR(SUM(G18:G22)/G9,"") | H33: =IFERROR(SUM(H18:H22)/H9,"")
B34: Please give explanation below, if OR-Margin% is below 0% or below Planned margin of its profit center
B37: Hourly Rate | D37: =IFERROR(VLOOKUP($D$3,$Q$4:$R$5,2,0),0) -> 681.98 | E37: =IFERROR(VLOOKUP($D$3,$Q$4:$R$5,2,0),0) -> 681.98 | F37: =IFERROR(VLOOKUP($D$3,$Q$4:$R$5,2,0),0) -> 681.98 | G37: =IFERROR(VLOOKUP($D$3,$Q$4:$R$5,2,0),0) -> 681.98 | H37: =IFERROR(VLOOKUP($D$3,$Q$4:$R$5,2,0),0) -> 681.98
B38: Hourly Rates / Allocation Costs | D38: =IFERROR(VLOOKUP($D$3,$Q$4:$U$5,5,0),0) -> 85.653125 | E38: =IFERROR(VLOOKUP($D$3,$Q$4:$U$5,5,0),0) -> 85.653125 | F38: =IFERROR(VLOOKUP($D$3,$Q$4:$U$5,5,0),0) -> 85.653125 | G38: =IFERROR(VLOOKUP($D$3,$Q$4:$U$5,5,0),0) -> 85.653125 | H38: =IFERROR(VLOOKUP($D$3,$Q$4:$U$5,5,0),0) -> 85.653125
B39: Allocation cost / Ext. sales | D39: =IFERROR(VLOOKUP($D$3,$Q$4:$V$5,6,0),0) -> 0.090531867 | E39: =IFERROR(VLOOKUP($D$3,$Q$4:$V$5,6,0),0) -> 0.090531867 | F39: =IFERROR(VLOOKUP($D$3,$Q$4:$V$5,6,0),0) -> 0.090531867 | G39: =IFERROR(VLOOKUP($D$3,$Q$4:$V$5,6,0),0) -> 0.090531867 | H39: =IFERROR(VLOOKUP($D$3,$Q$4:$V$5,6,0),0) -> 0.090531867
B40: Allocation cost / IC. sales
B41: Allocation cost by Ext. sales | D41: =D9*D39 -> 0 | E41: =E9*E39 -> 0 | F41: =F9*F39 -> 12493.398 | G41: =G9*G39 -> 0 | H41: =H9*H39 -> 0
B42: Allocation cost by IC sales | D42: =D9*D15*D40 -> 0 | E42: =E9*E15*E40 -> 0 | F42: =F9*F15*F40 -> 0 | G42: =G9*G15*G40 -> 0 | H42: =H9*H15*H40 -> 0
B43: Allocation costs by hour | D43: =D16*D38 -> 0 | E43: =E16*E38 -> 0 | F43: =F16*F38 -> 10209.852 | G43: =G16*G38 -> 0 | H43: =H16*H38 -> 0
B44: Allocation cost simulation | D44: =IF(D$4="2160",D41+D42-D43,D41-D43) -> 0 | E44: =IF(E$4="2160",E41+E42-E43,E41-E43) -> 0 | F44: =IF(F$4="2160",F41+F42-F43,F41-F43) -> 2283.5451 | G44: =IF(G$4="2160",G41+G42-G43,G41-G43) -> 0 | H44: =IF(H$4="2160",H41+H42-H43,H41-H43) -> 0
...

Sheet P&L
A1: C03 P&L complete
A3: Profit Center Hierarchy | B3: BL Greater China
A4: Profit Center | B4: 0001PS-ESG-GC PS-ESG-GC
A5: Target currency | B5: CNY CNY
A6: Date for currency conversion | B6: 31.12.2025
A7: Scale factor | B7: 1
A9: Dynamic Filters
A10: Time scale | B10: 16 Budget 2025 (2024); !17 Budget 2025 (2023)
A11: P&L Key figures | B11: Professional fees; Service Accounting/Procurement; Marketing; Management fee; Charging/Assessment; Sales; Consulting / Insurance; Total Costs; Computer Costs; Subcontracting; OR%
A12: BEx Web - C03 P&L complete
C13: 16 Budget 2026 (2025) | D13: 16 Budget 2026 (2025) | E13: 16 Budget 2026 (2025)
B14: Profit Center | C14: 0001PS-AUD-GC | D14: 0001PS-ESG-GC | E14: 0001PS-CSR-GC
A15: P&L Key figures | C15: PS AUD China op. | D15: PS-ESG-GC | E15: PS-CSR-GC
A16: Sales | C16: 56448147 | D16: 20584916 | E16: 35863231 | F16: =(_xlfn.XLOOKUP(A16,Mapping!C:C,Mapping!E:E,"")) | G16: =(_xlfn.XLOOKUP(A16,Mapping!C:C,Mapping!F:F,""))
A17: Ext. Sales | C17: 46755731 | D17: 13820706 | E17: 32935025 | F17: =(_xlfn.XLOOKUP(A17,Mapping!C:C,Mapping!E:E,"")) | G17: =(_xlfn.XLOOKUP(A17,Mapping!C:C,Mapping!F:F,""))
A18: IC Sales | C18: 9692416.5 | D18: 6764210.3 | E18: 2928206.2 | F18: =(_xlfn.XLOOKUP(A18,Mapping!C:C,Mapping!E:E,"")) | G18: =(_xlfn.XLOOKUP(A18,Mapping!C:C,Mapping!F:F,""))
A19: CtC (POC) | F19: =(_xlfn.XLOOKUP(A19,Mapping!C:C,Mapping!E:E,"")) | G19: =(_xlfn.XLOOKUP(A19,Mapping!C:C,Mapping!F:F,""))
A20: Subcontracting | C20: 20856759 | D20: 8963024 | E20: 11893735 | F20: =(_xlfn.XLOOKUP(A20,Mapping!C:C,Mapping!E:E,"")) | G20: =(_xlfn.XLOOKUP(A20,Mapping!C:C,Mapping!F:F,""))
A21: Subcontracting ext. | C21: 6995725.3 | D21: 2165228.8 | E21: 4830496.4 | F21: =(_xlfn.XLOOKUP(A21,Mapping!C:C,Mapping!E:E,"")) | G21: =(_xlfn.XLOOKUP(A21,Mapping!C:C,Mapping!F:F,""))
A22: Subcontracting IC | C22: 13861034 | D22: 6797795.2 | E22: 7063239 | F22: =(_xlfn.XLOOKUP(A22,Mapping!C:C,Mapping!E:E,"")) | G22: =(_xlfn.XLOOKUP(A22,Mapping!C:C,Mapping!F:F,""))
A23: Computer Costs | C23: 2019422.5 | D23: 516482.26 | E23: 1502940.3 | F23: =(_xlfn.XLOOKUP(A23,Mapping!C:C,Mapping!E:E,"")) | G23: =(_xlfn.XLOOKUP(A23,Mapping!C:C,Mapping!F:F,""))
A24: IT Applications | C24: 225619.16 | D24: 57986.56 | E24: 167632.6 | F24: =(_xlfn.XLOOKUP(A24,Mapping!C:C,Mapping!E:E,"")) | G24: =(_xlfn.XLOOKUP(A24,Mapping!C:C,Mapping!F:F,""))
A25: TUEV/49993409 | B25: IT - SAP costs IC | C25: 225619.16 | D25: 57986.56 | E25: 167632.6 | F25: =(_xlfn.XLOOKUP(A25,Mapping!C:C,Mapping!E:E,"")) | G25: =(_xlfn.XLOOKUP(A25,Mapping!C:C,Mapping!F:F,""))
A26: IT Consulting/Development | C26: 872417.76 | D26: 257880.72 | E26: 614537.04 | F26: =(_xlfn.XLOOKUP(A26,Mapping!C:C,Mapping!E:E,"")) | G26: =(_xlfn.XLOOKUP(A26,Mapping!C:C,Mapping!F:F,""))
A27: TUEV/49993509 | B27: IT - App. DV PS IC | C27: 872417.76 | D27: 257880.72 | E27: 614537.04 | F27: =(_xlfn.XLOOKUP(A27,Mapping!C:C,Mapping!E:E,"")) -> 1 | G27: =(_xlfn.XLOOKUP(A27,Mapping!C:C,Mapping!F:F,"")) -> ext. sales
A28: IT Infrastructure | F28: =(_xlfn.XLOOKUP(A28,Mapping!C:C,Mapping!E:E,"")) | G28: =(_xlfn.XLOOKUP(A28,Mapping!C:C,Mapping!F:F,""))
A29: IT Maintenance | F29: =(_xlfn.XLOOKUP(A29,Mapping!C:C,Mapping!E:E,"")) | G29: =(_xlfn.XLOOKUP(A29,Mapping!C:C,Mapping!F:F,""))
A30: IT Training | F30: =(_xlfn.XLOOKUP(A30,Mapping!C:C,Mapping!E:E,"")) | G30: =(_xlfn.XLOOKUP(A30,Mapping!C:C,Mapping!F:F,""))
A31: IT Allocation/Accumulation | C31: 921385.6 | D31: 200614.98 | E31: 720770.62 | F31: =(_xlfn.XLOOKUP(A31,Mapping!C:C,Mapping!E:E,"")) | G31: =(_xlfn.XLOOKUP(A31,Mapping!C:C,Mapping!F:F,""))
A32: TUEV/91015010 | B32: Assessment IT | C32: 921385.6 | D32: 200614.98 | E32: 720770.62 | F32: =(_xlfn.XLOOKUP(A32,Mapping!C:C,Mapping!E:E,"")) | G32: =(_xlfn.XLOOKUP(A32,Mapping!C:C,Mapping!F:F,""))
A33: Professional fees | C33: 297945.79 | D33: 488525.28 | E33: -190579.49 | F33: =(_xlfn.XLOOKUP(A33,Mapping!C:C,Mapping!E:E,"")) | G33: =(_xlfn.XLOOKUP(A33,Mapping!C:C,Mapping!F:F,""))
A34: TUEV/42213000 | B34: Professional Fee | C34: 48919.99 | D34: 34560 | E34: 14359.99 | F34: =(_xlfn.XLOOKUP(A34,Mapping!C:C,Mapping!E:E,"")) | G34: =(_xlfn.XLOOKUP(A34,Mapping!C:C,Mapping!F:F,""))
A35: TUEV/42213009 | B35: Professional Fee | C35: 0 | D35: 380355.96 | E35: -380355.96 | F35: =(_xlfn.XLOOKUP(A35,Mapping!C:C,Mapping!E:E,"")) | G35: =(_xlfn.XLOOKUP(A35,Mapping!C:C,Mapping!F:F,""))
A36: TUEV/49998009 | B36: BU/BL costs | C36: 249025.8 | D36: 73609.32 | E36: 175416.48 | F36: =(_xlfn.XLOOKUP(A36,Mapping!C:C,Mapping!E:E,"")) -> 1 | G36: =(_xlfn.XLOOKUP(A36,Mapping!C:C,Mapping!F:F,"")) -> ext. sales
A37: Service Accounting/Procurement | C37: 412395.51 | D37: 178020.35 | E37: 234375.16 | F37: =(_xlfn.XLOOKUP(A37,Mapping!C:C,Mapping!E:E,"")) | G37: =(_xlfn.XLOOKUP(A37,Mapping!C:C,Mapping!F:F,""))
A38: TUEV/91015090 | B38: Assessment Accountin | C38: 412395.51 | D38: 178020.35 | E38: 234375.16 | F38: =(_xlfn.XLOOKUP(A38,Mapping!C:C,Mapping!E:E,"")) -> 1 | G38: =(_xlfn.XLOOKUP(A38,Mapping!C:C,Mapping!F:F,"")) -> total sales
A39: Marketing | C39: 485296.76 | D39: 103580.08 | E39: 381716.68 | F39: =(_xlfn.XLOOKUP(A39,Mapping!C:C,Mapping!E:E,"")) | G39: =(_xlfn.XLOOKUP(A39,Mapping!C:C,Mapping!F:F,""))
A40: TUEV/49600700 | B40: Website and Intranet | C40: 139750.83 | D40: 41310.07 | E40: 98440.76 | F40: =(_xlfn.XLOOKUP(A40,Mapping!C:C,Mapping!E:E,"")) | G40: =(_xlfn.XLOOKUP(A40,Mapping!C:C,Mapping!F:F,""))
A41: TUEV/49601300 | B41: Offline trade fairs | C41: 145463.04 | D41: 42996.2 | E41: 102466.84 | F41: =(_xlfn.XLOOKUP(A41,Mapping!C:C,Mapping!E:E,"")) | G41: =(_xlfn.XLOOKUP(A41,Mapping!C:C,Mapping!F:F,""))
A42: TUEV/91015040 | B42: Assessment Marketing | C42: 200082.89 | D42: 19273.81 | E42: 180809.08 | F42: =(_xlfn.XLOOKUP(A42,Mapping!C:C,Mapping!E:E,"")) -> 1 | G42: =(_xlfn.XLOOKUP(A42,Mapping!C:C,Mapping!F:F,"")) -> ext. sales
...

Sheet Hourly Rate
A1: C83 Overview hourly rates
A3: Profit Center Hierarchy | B3: BL Greater China (0001CN-GF-ALL)
A4: Profit Center Hierarchy Node | B4: 0001PS-AUD-GC PS AUD China op.
A5: Last Data Update | B5: 09.04.2025 14:06:27
A7: Dynamic Filters
A8: Activity Type | B8: T01AST
A9: BEx Web - ZKSTDSAETZE_01
A10: Profit Center | C10: Activity Type | D10: Skillgroup | E10: Local Currency | F10: Settlement Own work (ZCOILV30) | G10: Settlement Int. performance (ZCOILV30) | H10: Settlement non-productive (ZCOILV30) | I10: Settlement (KP26 Version 0) 2026 | J10: Calculation (KP26 Version 1) 2026 | K10: CtC
A11: 18001350 | B11: HK PS CPS AUD | C11: T01AST | D11: 0180/# | E11: HKD | F11: 756.87 | G11: 756.87 | H11: 0 | I11: 756.87 | J11: 756.87 | K11: 236.89
A12: 18001351 | B12: HK PS CPS AUD CSR | C12: T01AST | D12: 0180/# | E12: HKD | F12: 590.7 | G12: 590.7 | H12: 0 | I12: 479.61 | J12: 479.61 | K12: 236.89
A13: 21601350 | B13: PSB Electr. PS AUD | C13: T01AST | D13: 0216/# | E13: CNY | F13: 681.98 | G13: 681.98 | H13: 0 | I13: 681.98 | J13: 681.98 | K13: 289.35
A14: 34601350 | B14: GI PS CPS AUD | C14: T01AST | D14: 0346/# | E14: HKD | I14: 1 | J14: 0.98 | K14: 0
A15: 48201222 | B15: SHG PS CPS HDL eCom | C15: T01AST | D15: 0482/# | E15: CNY | F15: 879.03 | G15: 879.03 | H15: 0 | I15: 879.03 | J15: 879.03 | K15: 289.35
A16: 48201350 | B16: SHG PS CPS AUD | C16: T01AST | D16: 0482/# | E16: CNY | F16: 681.98 | G16: 681.98 | H16: 0 | I16: 681.98 | J16: 681.98 | K16: 289.35
A17: 48201351 | B17: SHG PS CPS AUD CSR | C17: T01AST | D17: 0482/# | E17: CNY | F17: 532.25 | G17: 532.25 | H17: 0 | I17: 443.06 | J17: 443.06 | K17: 289.35
A18: 48301350 | B18: BJS PS CPS AUD | C18: T01AST | D18: 0483/# | E18: CNY | F18: 681.98 | G18: 681.98 | H18: 0 | I18: 681.98 | J18: 681.98 | K18: 308.84
A19: 48301351 | B19: BJS PS CPS AUD CSR | C19: T01AST | D19: 0483/# | E19: CNY | F19: 532.25 | G19: 532.25 | H19: 0 | I19: 443.06 | J19: 443.06 | K19: 135.98
A20: 48401350 | B20: CAN PS CPS AUD | C20: T01AST | D20: 0484/# | E20: CNY | F20: 681.98 | G20: 681.98 | H20: 0 | I20: 681.98 | J20: 681.98 | K20: 175.74
A21: 48401351 | B21: CAN PS CPS AUD CSR | C21: T01AST | D21: 0484/# | E21: CNY | F21: 532.25 | G21: 532.25 | H21: 0 | I21: 443.06 | J21: 443.06 | K21: 175.74
A22: 48501350 | B22: SHZ PS CPS AUD | C22: T01AST | D22: 0485/# | E22: CNY | F22: 681.98 | G22: 681.98 | H22: 0 | I22: 681.98 | J22: 681.98 | K22: 196.33
A23: 48501351 | B23: SHZ PS CPS AUD CSR | C23: T01AST | D23: 0485/# | E23: CNY | F23: 532.25 | G23: 532.25 | H23: 0 | I23: 532.25 | J23: 532.25 | K23: 196.33

Sheet Mapping
A1: Data source: Account codes to be exacted from BW report-P&L-C00 P&L
A2: Items | B2: Account | C2: Account code | D2: Description | E2: Prorata
A3: 1 | B3: Professional fees | C3: TUEV/49998009 | D3: BU/BL costs | E3: 1 | F3: ext. sales
A4: 2 | B4: Accounting Service | C4: TUEV/91015090 | D4: Accounting | E4: 1 | F4: total sales | G4: new GL account
A5: 3 | B5: Marketing | C5: TUEV/49992309 | D5: Services Marketing | E5: 1 | F5: ext. sales
A6: 4 | B6: Marketing | C6: TUEV/91351007 | D6: Marketing | E6: 1 | F6: ext. sales | G6: new GL account
A7: 5 | B7: Marketing | C7: TUEV/91015040 | D7: Marketing | E7: 1 | F7: ext. sales | G7: new GL account
A8: 6 | B8: Management fee | C8: TUEV/49994008 | D8: Service charges CN | E8: 1 | F8: ext. sales
A9: 7 | B9: Management fee | C9: TUEV/49994009 | D9: Service charges CN | E9: 1 | F9: ext. sales
A10: 8 | B10: Management fee | C10: TUEV/49994109 | D10: Service charges CN | E10: 1 | F10: ext. sales | G10: new add in 2019
A11: 9 | B11: Management fee | C11: TUEV/49995009 | D11: Services divisions | E11: 1 | F11: ext. sales
A12: 10 | B12: Management fee | C12: TUEV/49995109 | D12: Division costs | E12: 1 | F12: ext. sales
A13: 11 | B13: Management fee | C13: TUEV/49997009 | D13: Services Region | E13: 1 | F13: ext. sales
A14: 12 | B14: Management fee | C14: TUEV/49997108 | D14: Services Region | E14: 1 | F14: ext. sales
A15: 13 | B15: Management fee | C15: TUEV/49997109 | D15: Services Region | E15: 1 | F15: ext. sales
A16: 14 | B16: Management fee | C16: TUEV/49999009 | D16: Management fee AG | E16: 1 | F16: ext. sales
A17: 15 | B17: Charging/Assessment | C17: TUEV/91011040 | D17: Controlling | E17: 0.5 | F17: total sales | G17: new GL account
A18: 16 | B18: Charging/Assessment | C18: TUEV/91351000 | D18: General Costs | E18: 0.5 | F18: net. Sales | G18: new GL account
A19: 17 | B19: Charging/Assessment | C19: TUEV/91351001 | D19: CEO/ADM | E19: 0.5 | F19: net. Sales | G19: new GL account
A20: 18 | B20: Charging/Assessment | C20: TUEV/91351017 | D20: Sales | E20: 1 | F20: ext. sales | G20: new GL account
A21: 19 | B21: Charging/Assessment | C21: TUEV/91110031 | D21: Procurement | E21: 0.5 | F21: ext. sales | G21: new GL account
A22: 20 | B22: Charging/Assessment | C22: TUEV/91351008 | D22: Certification | E22: 1 | F22: ext. sales | G22: new GL account
A23: 21 | B23: Computer cost | C23: TUEV/49993509 | D23: IT opex | E23: 1 | F23: ext. sales | G23: new add in 2020
A24: 22 | B24: Service Accounting | C24: TUEV/49991009 | D24: Service Accounting | E24: 1 | F24: ext. sales | G24: new add in 2022
A25: 23 | B25: Service Procurement | C25: TUEV/49991609 | D25: Service Procurement | E25: 0.5 | F25: ext. sales | G25: new add in 2022
A26: 24 | B26: Charging/Assessment | C26: TUEV/91011050 | D26: Management (CEO) | E26: 1 | F26: ext. sales | G26: new add in 2023
